Loading rhel8/default-amp
  Loading requirement: rhel8/slurm singularity/current rhel8/global cuda/11.4
    libpciaccess/0.16/gcc-9.4.0-6fonbj6 libiconv/1.16/gcc-9.4.0-ahebbov
    libxml2/2.9.12/gcc-9.4.0-gnknt5e ncurses/6.2/gcc-9.4.0-aiirok7
    hwloc/2.5.0/gcc-9.4.0-7sqomga libevent/2.1.12/gcc-9.4.0-hgny7cm
    numactl/2.0.14/gcc-9.4.0-52dwc6n cuda/11.4.0/gcc-9.4.0-3hnxhjt
    gdrcopy/2.2/gcc-9.4.0-e4igtfp knem/1.1.4/gcc-9.4.0-bpbxgva
    libnl/3.3.0/gcc-9.4.0-whwhrwb rdma-core/34.0/gcc-9.4.0-5eo5n2u
    ucx/1.11.1/gcc-9.4.0-lktqyl4 openmpi/4.1.1/gcc-9.4.0-epagguv
/var/spool/slurm/slurmd/job9410202/slurm_script: line 65: conda: command not found
Changed directory to /rds/user/ana42/hpc-work/sae_entities.

JobID: 9410202
======
Time: Thu May 15 18:39:42 BST 2025
Running on master node: gpu-q-33
Current directory: /rds/user/ana42/hpc-work/sae_entities

Nodes allocated:
================
gpu-q-33

numtasks=1, numnodes=1, mpi_tasks_per_node=1 (OMP_NUM_THREADS=1)

Executing command:
==================
python -u data_labelling.py  > logs/out.9410202

Downloading shards:   0%|          | 0/3 [00:00<?, ?it/s]Downloading shards:   0%|          | 0/3 [01:14<?, ?it/s]
Traceback (most recent call last):
  File "/rds/user/ana42/hpc-work/sae_entities/data_labelling.py", line 75, in <module>
    model = AutoModelForCausalLM.from_pretrained(
            ^^^^^^^^^^^^^^^^^^^^^^^^^^^^^^^^^^^^^
  File "/rds/user/ana42/hpc-work/sae_entities/.venv/lib64/python3.11/site-packages/transformers/models/auto/auto_factory.py", line 564, in from_pretrained
    return model_class.from_pretrained(
           ^^^^^^^^^^^^^^^^^^^^^^^^^^^^
  File "/rds/user/ana42/hpc-work/sae_entities/.venv/lib64/python3.11/site-packages/transformers/modeling_utils.py", line 3715, in from_pretrained
    resolved_archive_file, sharded_metadata = get_checkpoint_shard_files(
                                              ^^^^^^^^^^^^^^^^^^^^^^^^^^^
  File "/rds/user/ana42/hpc-work/sae_entities/.venv/lib64/python3.11/site-packages/transformers/utils/hub.py", line 1079, in get_checkpoint_shard_files
    cached_filename = cached_file(
                      ^^^^^^^^^^^^
  File "/rds/user/ana42/hpc-work/sae_entities/.venv/lib64/python3.11/site-packages/transformers/utils/hub.py", line 402, in cached_file
    resolved_file = hf_hub_download(
                    ^^^^^^^^^^^^^^^^
  File "/rds/user/ana42/hpc-work/sae_entities/.venv/lib64/python3.11/site-packages/huggingface_hub/utils/_deprecation.py", line 101, in inner_f
    return f(*args, **kwargs)
           ^^^^^^^^^^^^^^^^^^
  File "/rds/user/ana42/hpc-work/sae_entities/.venv/lib64/python3.11/site-packages/huggingface_hub/utils/_validators.py", line 114, in _inner_fn
    return fn(*args, **kwargs)
           ^^^^^^^^^^^^^^^^^^^
  File "/rds/user/ana42/hpc-work/sae_entities/.venv/lib64/python3.11/site-packages/huggingface_hub/file_download.py", line 1232, in hf_hub_download
    return _hf_hub_download_to_cache_dir(
           ^^^^^^^^^^^^^^^^^^^^^^^^^^^^^^
  File "/rds/user/ana42/hpc-work/sae_entities/.venv/lib64/python3.11/site-packages/huggingface_hub/file_download.py", line 1381, in _hf_hub_download_to_cache_dir
    _download_to_tmp_and_move(
  File "/rds/user/ana42/hpc-work/sae_entities/.venv/lib64/python3.11/site-packages/huggingface_hub/file_download.py", line 1903, in _download_to_tmp_and_move
    with incomplete_path.open("ab") as f:
OSError: [Errno 28] No space left on device
